import tests.test_network
tests.test_network.test_exception()